Workbook

Sheet Respuestas de formulario 1
A1: {=L:L&G:G} -> MARCA TEMPORALMÓVIL | B1: Marca temporal | C1: {=IFERROR(IF(B:B="","",TEXT(B:B,"dd")),"DIA")} -> Marca temporal | D1: {=IFERROR(IF(B:B="","",TEXT(B:B,"mm")),"MES")} -> Marca temporal | E1: {=IFERROR(IF(B:B="","",YEAR(B:B)),"AÑO")} -> AÑO | F1: {=B:B} -> Marca temporal | G1: MÓVIL | H1: CALIFIQUE QUE TAN SUCIO ESTABA EL VEHÍCULO ANTES DEL LAVADO. DONDE 1 ES MUY LIMPIO Y 5 ES MUY SUCIO. | I1: ¿CUANTAS PERSONAS PARTICIPARON EN LA INTERVENCIÓN? | J1: Califique el servicio prestado en el lavadero externo (espacio único para satélite Rionegro) | L1: {=UPPER(M:M)} -> MARCA TEMPORAL | M1: {=IF(B:B="","",TEXT(B:B,"MMMM"))} -> Marca temporal
A2: DICIEMBRE2563 | B2: 44915.41 | C2: 20 | D2: 12 | E2: 2022 | F2: 44915.41 | G2: 2563 | H2: VEHÍCULO APROPIADO PARA LAVADO | L2: DICIEMBRE | M2: diciembre | N2: =B2 -> 44915.41
A3: DICIEMBRE2628 | B3: 44915.41 | C3: 20 | D3: 12 | E3: 2022 | F3: 44915.41 | G3: 2628 | H3: VEHÍCULO APROPIADO PARA LAVADO | L3: DICIEMBRE | M3: diciembre
A4: DICIEMBRE2469 | B4: 44915.41 | C4: 20 | D4: 12 | E4: 2022 | F4: 44915.41 | G4: 2469 | H4: VEHÍCULO APROPIADO PARA LAVADO | L4: DICIEMBRE | M4: diciembre
A5: DICIEMBRE2677 | B5: 44915.41 | C5: 20 | D5: 12 | E5: 2022 | F5: 44915.41 | G5: 2677 | H5: VEHÍCULO APROPIADO PARA LAVADO | L5: DICIEMBRE | M5: diciembre
A6: DICIEMBRE2194 | B6: 44915.411 | C6: 20 | D6: 12 | E6: 2022 | F6: 44915.411 | G6: 2194 | H6: VEHÍCULO APROPIADO PARA LAVADO | L6: DICIEMBRE | M6: diciembre
A7: DICIEMBRE2460 | B7: 44915.411 | C7: 20 | D7: 12 | E7: 2022 | F7: 44915.411 | G7: 2460 | H7: VEHÍCULO APROPIADO PARA LAVADO | L7: DICIEMBRE | M7: diciembre
A8: DICIEMBRE2669 | B8: 44915.411 | C8: 20 | D8: 12 | E8: 2022 | F8: 44915.411 | G8: 2669 | H8: VEHÍCULO APROPIADO PARA LAVADO | L8: DICIEMBRE | M8: diciembre
A9: DICIEMBRE2189 | B9: 44915.411 | C9: 20 | D9: 12 | E9: 2022 | F9: 44915.411 | G9: 2189 | H9: VEHÍCULO APROPIADO PARA LAVADO | L9: DICIEMBRE | M9: diciembre
A10: DICIEMBRE2629 | B10: 44915.411 | C10: 20 | D10: 12 | E10: 2022 | F10: 44915.411 | G10: 2629 | H10: VEHÍCULO APROPIADO PARA LAVADO | L10: DICIEMBRE | M10: diciembre
A11: DICIEMBRE2367 | B11: 44915.411 | C11: 20 | D11: 12 | E11: 2022 | F11: 44915.411 | G11: 2367 | H11: VEHÍCULO APROPIADO PARA LAVADO | L11: DICIEMBRE | M11: diciembre
A12: DICIEMBRE2563 | B12: 44915.412 | C12: 20 | D12: 12 | E12: 2022 | F12: 44915.412 | G12: 2563 | H12: VEHÍCULO APROPIADO PARA LAVADO | L12: DICIEMBRE | M12: diciembre
A13: DICIEMBRE2400 | B13: 44916.271 | C13: 21 | D13: 12 | E13: 2022 | F13: 44916.271 | G13: 2400 | H13: VEHÍCULO APROPIADO PARA LAVADO | L13: DICIEMBRE | M13: diciembre
A14: DICIEMBRE2369 | B14: 44916.272 | C14: 21 | D14: 12 | E14: 2022 | F14: 44916.272 | G14: 2369 | H14: VEHÍCULO APROPIADO PARA LAVADO | L14: DICIEMBRE | M14: diciembre
... A78: ENERO2671 | B78: 44930.275 | C78: 04 | D78: 01 | E78: 2023 | F78: 44930.275 | G78: 2671 | H78: EL VEHÍCULO SE ENCONTRABA MUY SUCIO | L78: ENERO | M78: enero
A79: ENEROKHN937 | B79: 44930.601 | C79: 04 | D79: 01 | E79: 2023 | F79: 44930.601 | G79: KHN937 | H79: EL VEHÍCULO SE ENCONTRABA MUY SUCIO | L79: ENERO | M79: enero
A80: ENERO2460 | B80: 44930.97 | C80: 04 | D80: 01 | E80: 2023 | F80: 44930.97 | G80: 2460 | H80: VEHÍCULO APROPIADO PARA LAVADO | L80: ENERO | M80: enero
A81: ENERO2458 | B81: 44931.029 | C81: 05 | D81: 01 | E81: 2023 | F81: 44931.029 | G81: 2458 | H81: VEHÍCULO APROPIADO PARA LAVADO | L81: ENERO | M81: enero
A82: ENERO2659 | B82: 44931.064 | C82: 05 | D82: 01 | E82: 2023 | F82: 44931.064 | G82: 2659 | H82: VEHÍCULO APROPIADO PARA LAVADO | L82: ENERO | M82: enero
A83: ENERO2436 | B83: 44931.103 | C83: 05 | D83: 01 | E83: 2023 | F83: 44931.103 | G83: 2436 | H83: VEHÍCULO APROPIADO PARA LAVADO | L83: ENERO | M83: enero
A84: ENERO2339 | B84: 44931.158 | C84: 05 | D84: 01 | E84: 2023 | F84: 44931.158 | G84: 2339 | H84: VEHÍCULO APROPIADO PARA LAVADO | L84: ENERO | M84: enero
A85: ENERO2273 | B85: 44931.186 | C85: 05 | D85: 01 | E85: 2023 | F85: 44931.186 | G85: 2273 | H85: VEHÍCULO APROPIADO PARA LAVADO | L85: ENERO | M85: enero
A86: ENERO2456 | B86: 44931.221 | C86: 05 | D86: 01 | E86: 2023 | F86: 44931.221 | G86: 2456 | H86: VEHÍCULO APROPIADO PARA LAVADO | L86: ENERO | M86: enero
A87: ENERO2238 | B87: 44931.382 | C87: 05 | D87: 01 | E87: 2023 | F87: 44931.382 | G87: 2238 | H87: VEHÍCULO APROPIADO PARA LAVADO | L87: ENERO | M87: enero
A88: ENERO1798 | B88: 44931.464 | C88: 05 | D88: 01 | E88: 2023 | F88: 44931.464 | G88: 1798 | H88: VEHÍCULO APROPIADO PARA LAVADO | L88: ENERO | M88: enero
A89: ENERO2682 | B89: 44931.986 | C89: 05 | D89: 01 | E89: 2023 | F89: 44931.986 | G89: 2682 | H89: VEHÍCULO APROPIADO PARA LAVADO | L89: ENERO | M89: enero
A90: ENERO2663 | B90: 44932.021 | C90: 06 | D90: 01 | E90: 2023 | F90: 44932.021 | G90: 2663 | H90: VEHÍCULO APROPIADO PARA LAVADO | L90: ENERO | M90: enero
A91: ENERO2355 | B91: 44932.053 | C91: 06 | D91: 01 | E91: 2023 | F91: 44932.053 | G91: 2355 | H91: VEHÍCULO APROPIADO PARA LAVADO | L91: ENERO | M91: enero
... A190: ENERO2637 | B190: 44942.339 | C190: 16 | D190: 01 | E190: 2023 | F190: 44942.339 | G190: 2637 | H190: VEHÍCULO APROPIADO PARA LAVADO | L190: ENERO | M190: enero
A191: ENEROKHN152 | B191: 44942.356 | C191: 16 | D191: 01 | E191: 2023 | F191: 44942.356 | G191: KHN152 | H191: VEHÍCULO APROPIADO PARA LAVADO | L191: ENERO | M191: enero
A192: ENERO2666 | B192: 44942.38 | C192: 16 | D192: 01 | E192: 2023 | F192: 44942.38 | G192: 2666 | H192: EL VEHÍCULO SE ENCONTRABA MUY SUCIO | L192: ENERO | M192: enero
A193: ENEROIAZ451 | B193: 44942.395 | C193: 16 | D193: 01 | E193: 2023 | F193: 44942.395 | G193: IAZ451 | H193: VEHÍCULO APROPIADO PARA LAVADO | L193: ENERO | M193: enero
A194: ENEROJHU739 | B194: 44942.482 | C194: 16 | D194: 01 | E194: 2023 | F194: 44942.482 | G194: JHU739 | H194: VEHÍCULO APROPIADO PARA LAVADO | L194: ENERO | M194: enero
A195: ENEROMNK264 | B195: 44942.535 | C195: 16 | D195: 01 | E195: 2023 | F195: 44942.535 | G195: MNK264 | H195: VEHÍCULO APROPIADO PARA LAVADO | L195: ENERO | M195: enero
A196: ENERO2679 | B196: 44942.558 | C196: 16 | D196: 01 | E196: 2023 | F196: 44942.558 | G196: 2679 | H196: VEHÍCULO APROPIADO PARA LAVADO | L196: ENERO | M196: enero
A197: ENEROKHQ888 | B197: 44942.614 | C197: 16 | D197: 01 | E197: 2023 | F197: 44942.614 | G197: KHQ888 | H197: VEHÍCULO APROPIADO PARA LAVADO | L197: ENERO | M197: enero
A198: ENEROKHN937 | B198: 44942.64 | C198: 16 | D198: 01 | E198: 2023 | F198: 44942.64 | G198: KHN937 | H198: VEHÍCULO APROPIADO PARA LAVADO | L198: ENERO | M198: enero
A199: ENERO2630 | B199: 44942.95 | C199: 16 | D199: 01 | E199: 2023 | F199: 44942.95 | G199: 2630 | H199: VEHÍCULO APROPIADO PARA LAVADO | L199: ENERO | M199: enero
A200: ENERO2677 | B200: 44942.982 | C200: 16 | D200: 01 | E200: 2023 | F200: 44942.982 | G200: 2677 | H200: VEHÍCULO APROPIADO PARA LAVADO | L200: ENERO | M200: enero
A201: ENERO2206 | B201: 44943.013 | C201: 17 | D201: 01 | E201: 2023 | F201: 44943.013 | G201: 2206 | H201: VEHÍCULO APROPIADO PARA LAVADO | L201: ENERO | M201: enero
...

Sheet BASE T MPP
A1: =IFERROR(__xludf.DUMMYFUNCTION("QUERY(FORM!A:J,""SELECT B,A,C,D,J ORDER BY A DESC"",1)"),"#REF!") -> #REF!

Sheet RECURSO ACTUAL
A1: =IFERROR(__xludf.DUMMYFUNCTION("IMPORTRANGE(""https://docs.google.com/spreadsheets/d/1m7J6Y1SSBkQdcMVXl2Yj-j28gyJMAbS4UK0IL9qsiNA/edit?gid=0#gid=0"",""ANTIOQUIA!A:H"")"),"MOVIL") -> MOVIL | B1: =IFERROR(__xludf.DUMMYFUNCTION("""COMPUTED_VALUE"""),"POBLACIÓN") -> POBLACIÓN | C1: =IFERROR(__xludf.DUMMYFUNCTION("""COMPUTED_VALUE"""),"PLACA") -> PLACA | D1: =IFERROR(__xludf.DUMMYFUNCTION("""COMPUTED_VALUE"""),"LINEA") -> LINEA | E1: =IFERROR(__xludf.DUMMYFUNCTION("""COMPUTED_VALUE"""),"SOAT") -> SOAT | F1: =IFERROR(__xludf.DUMMYFUNCTION("""COMPUTED_VALUE"""),"RTM") -> RTM
A2: =IFERROR(__xludf.DUMMYFUNCTION("""COMPUTED_VALUE"""),3284.0) -> 3284 | B2: =IFERROR(__xludf.DUMMYFUNCTION("""COMPUTED_VALUE"""),"02-Medellin") -> 02-Medellin | C2: =IFERROR(__xludf.DUMMYFUNCTION("""COMPUTED_VALUE"""),"PVS650") -> PVS650 | D2: =IFERROR(__xludf.DUMMYFUNCTION("""COMPUTED_VALUE"""),"FURGON FOTON 1030") -> FURGON FOTON 1030 | E2: =IFERROR(__xludf.DUMMYFUNCTION("""COMPUTED_VALUE"""),46301.0) -> 46301 | F2: =IFERROR(__xludf.DUMMYFUNCTION("""COMPUTED_VALUE"""),46668.0) -> 46668
A3: =IFERROR(__xludf.DUMMYFUNCTION("""COMPUTED_VALUE"""),3283.0) -> 3283 | B3: =IFERROR(__xludf.DUMMYFUNCTION("""COMPUTED_VALUE"""),"02-Medellin") -> 02-Medellin | C3: =IFERROR(__xludf.DUMMYFUNCTION("""COMPUTED_VALUE"""),"PVS649") -> PVS649 | D3: =IFERROR(__xludf.DUMMYFUNCTION("""COMPUTED_VALUE"""),"FURGON FOTON 1030") -> FURGON FOTON 1030 | E3: =IFERROR(__xludf.DUMMYFUNCTION("""COMPUTED_VALUE"""),46301.0) -> 46301 | F3: =IFERROR(__xludf.DUMMYFUNCTION("""COMPUTED_VALUE"""),46668.0) -> 46668
A4: =IFERROR(__xludf.DUMMYFUNCTION("""COMPUTED_VALUE"""),3282.0) -> 3282 | B4: =IFERROR(__xludf.DUMMYFUNCTION("""COMPUTED_VALUE"""),"02-Medellin") -> 02-Medellin | C4: =IFERROR(__xludf.DUMMYFUNCTION("""COMPUTED_VALUE"""),"PVS648") -> PVS648 | D4: =IFERROR(__xludf.DUMMYFUNCTION("""COMPUTED_VALUE"""),"FURGON FOTON 1030") -> FURGON FOTON 1030 | E4: =IFERROR(__xludf.DUMMYFUNCTION("""COMPUTED_VALUE"""),46301.0) -> 46301 | F4: =IFERROR(__xludf.DUMMYFUNCTION("""COMPUTED_VALUE"""),46668.0) -> 46668
A5: =IFERROR(__xludf.DUMMYFUNCTION("""COMPUTED_VALUE"""),3281.0) -> 3281 | B5: =IFERROR(__xludf.DUMMYFUNCTION("""COMPUTED_VALUE"""),"02-Medellin") -> 02-Medellin | C5: =IFERROR(__xludf.DUMMYFUNCTION("""COMPUTED_VALUE"""),"PVS647") -> PVS647 | D5: =IFERROR(__xludf.DUMMYFUNCTION("""COMPUTED_VALUE"""),"FURGON FOTON 1030") -> FURGON FOTON 1030 | E5: =IFERROR(__xludf.DUMMYFUNCTION("""COMPUTED_VALUE"""),46301.0) -> 46301 | F5: =IFERROR(__xludf.DUMMYFUNCTION("""COMPUTED_VALUE"""),46668.0) -> 46668
A6: =IFERROR(__xludf.DUMMYFUNCTION("""COMPUTED_VALUE"""),3280.0) -> 3280 | B6: =IFERROR(__xludf.DUMMYFUNCTION("""COMPUTED_VALUE"""),"02-Medellin") -> 02-Medellin | C6: =IFERROR(__xludf.DUMMYFUNCTION("""COMPUTED_VALUE"""),"PVS646") -> PVS646 | D6: =IFERROR(__xludf.DUMMYFUNCTION("""COMPUTED_VALUE"""),"FURGON FOTON 1030") -> FURGON FOTON 1030 | E6: =IFERROR(__xludf.DUMMYFUNCTION("""COMPUTED_VALUE"""),46301.0) -> 46301 | F6: =IFERROR(__xludf.DUMMYFUNCTION("""COMPUTED_VALUE"""),46668.0) -> 46668
A7: =IFERROR(__xludf.DUMMYFUNCTION("""COMPUTED_VALUE"""),3279.0) -> 3279 | B7: =IFERROR(__xludf.DUMMYFUNCTION("""COMPUTED_VALUE"""),"02-Medellin") -> 02-Medellin | C7: =IFERROR(__xludf.DUMMYFUNCTION("""COMPUTED_VALUE"""),"PVS645") -> PVS645 | D7: =IFERROR(__xludf.DUMMYFUNCTION("""COMPUTED_VALUE"""),"FURGON FOTON 1030") -> FURGON FOTON 1030 | E7: =IFERROR(__xludf.DUMMYFUNCTION("""COMPUTED_VALUE"""),46301.0) -> 46301 | F7: =IFERROR(__xludf.DUMMYFUNCTION("""COMPUTED_VALUE"""),46668.0) -> 46668
A8: =IFERROR(__xludf.DUMMYFUNCTION("""COMPUTED_VALUE"""),3278.0) -> 3278 | B8: =IFERROR(__xludf.DUMMYFUNCTION("""COMPUTED_VALUE"""),"02-Medellin") -> 02-Medellin | C8: =IFERROR(__xludf.DUMMYFUNCTION("""COMPUTED_VALUE"""),"PVS644") -> PVS644 | D8: =IFERROR(__xludf.DUMMYFUNCTION("""COMPUTED_VALUE"""),"FURGON FOTON 1030") -> FURGON FOTON 1030 | E8: =IFERROR(__xludf.DUMMYFUNCTION("""COMPUTED_VALUE"""),46301.0) -> 46301 | F8: =IFERROR(__xludf.DUMMYFUNCTION("""COMPUTED_VALUE"""),46668.0) -> 46668
A9: =IFERROR(__xludf.DUMMYFUNCTION("""COMPUTED_VALUE"""),3275.0) -> 3275 | B9: =IFERROR(__xludf.DUMMYFUNCTION("""COMPUTED_VALUE"""),"02-Medellin") -> 02-Medellin | C9: =IFERROR(__xludf.DUMMYFUNCTION("""COMPUTED_VALUE"""),"PVS641") -> PVS641 | D9: =IFERROR(__xludf.DUMMYFUNCTION("""COMPUTED_VALUE"""),"FURGON FOTON 1030") -> FURGON FOTON 1030 | E9: =IFERROR(__xludf.DUMMYFUNCTION("""COMPUTED_VALUE"""),46301.0) -> 46301 | F9: =IFERROR(__xludf.DUMMYFUNCTION("""COMPUTED_VALUE"""),46668.0) -> 46668
A10: =IFERROR(__xludf.DUMMYFUNCTION("""COMPUTED_VALUE"""),3273.0) -> 3273 | B10: =IFERROR(__xludf.DUMMYFUNCTION("""COMPUTED_VALUE"""),"02-Medellin") -> 02-Medellin | C10: =IFERROR(__xludf.DUMMYFUNCTION("""COMPUTED_VALUE"""),"PVS639") -> PVS639 | D10: =IFERROR(__xludf.DUMMYFUNCTION("""COMPUTED_VALUE"""),"FURGON FOTON 1030") -> FURGON FOTON 1030 | E10: =IFERROR(__xludf.DUMMYFUNCTION("""COMPUTED_VALUE"""),46301.0) -> 46301 | F10: =IFERROR(__xludf.DUMMYFUNCTION("""COMPUTED_VALUE"""),46668.0) -> 46668
A11: =IFERROR(__xludf.DUMMYFUNCTION("""COMPUTED_VALUE"""),3271.0) -> 3271 | B11: =IFERROR(__xludf.DUMMYFUNCTION("""COMPUTED_VALUE"""),"02-Medellin") -> 02-Medellin | C11: =IFERROR(__xludf.DUMMYFUNCTION("""COMPUTED_VALUE"""),"PVS637") -> PVS637 | D11: =IFERROR(__xludf.DUMMYFUNCTION("""COMPUTED_VALUE"""),"FURGON FOTON 1030") -> FURGON FOTON 1030 | E11: =IFERROR(__xludf.DUMMYFUNCTION("""COMPUTED_VALUE"""),46301.0) -> 46301 | F11: =IFERROR(__xludf.DUMMYFUNCTION("""COMPUTED_VALUE"""),46668.0) -> 46668
A12: =IFERROR(__xludf.DUMMYFUNCTION("""COMPUTED_VALUE"""),3264.0) -> 3264 | B12: =IFERROR(__xludf.DUMMYFUNCTION("""COMPUTED_VALUE"""),"02-Medellin") -> 02-Medellin | C12: =IFERROR(__xludf.DUMMYFUNCTION("""COMPUTED_VALUE"""),"PVS630") -> PVS630 | D12: =IFERROR(__xludf.DUMMYFUNCTION("""COMPUTED_VALUE"""),"FURGON FOTON 1030") -> FURGON FOTON 1030 | E12: =IFERROR(__xludf.DUMMYFUNCTION("""COMPUTED_VALUE"""),46301.0) -> 46301 | F12: =IFERROR(__xludf.DUMMYFUNCTION("""COMPUTED_VALUE"""),46668.0) -> 46668
A13: =IFERROR(__xludf.DUMMYFUNCTION("""COMPUTED_VALUE"""),3256.0) -> 3256 | B13: =IFERROR(__xludf.DUMMYFUNCTION("""COMPUTED_VALUE"""),"02-Medellin") -> 02-Medellin | C13: =IFERROR(__xludf.DUMMYFUNCTION("""COMPUTED_VALUE"""),"PVS622") -> PVS622 | D13: =IFERROR(__xludf.DUMMYFUNCTION("""COMPUTED_VALUE"""),"FURGON FOTON 1030") -> FURGON FOTON 1030 | E13: =IFERROR(__xludf.DUMMYFUNCTION("""COMPUTED_VALUE"""),46301.0) -> 46301 | F13: =IFERROR(__xludf.DUMMYFUNCTION("""COMPUTED_VALUE"""),46668.0) -> 46668
A14: =IFERROR(__xludf.DUMMYFUNCTION("""COMPUTED_VALUE"""),3252.0) -> 3252 | B14: =IFERROR(__xludf.DUMMYFUNCTION("""COMPUTED_VALUE"""),"24-Rionegro") -> 24-Rionegro | C14: =IFERROR(__xludf.DUMMYFUNCTION("""COMPUTED_VALUE"""),"PVS619") -> PVS619 | D14: =IFERROR(__xludf.DUMMYFUNCTION("""COMPUTED_VALUE"""),"FURGON FOTON 1030") -> FURGON FOTON 1030 | E14: =IFERROR(__xludf.DUMMYFUNCTION("""COMPUTED_VALUE"""),46295.0) -> 46295 | F14: =IFERROR(__xludf.DUMMYFUNCTION("""COMPUTED_VALUE"""),46661.0) -> 46661
A15: =IFERROR(__xludf.DUMMYFUNCTION("""COMPUTED_VALUE"""),3251.0) -> 3251 | B15: =IFERROR(__xludf.DUMMYFUNCTION("""COMPUTED_VALUE"""),"24-Rionegro") -> 24-Rionegro | C15: =IFERROR(__xludf.DUMMYFUNCTION("""COMPUTED_VALUE"""),"PVS618") -> PVS618 | D15: =IFERROR(__xludf.DUMMYFUNCTION("""COMPUTED_VALUE"""),"FURGON FOTON 1030") -> FURGON FOTON 1030 | E15: =IFERROR(__xludf.DUMMYFUNCTION("""COMPUTED_VALUE"""),46295.0) -> 46295 | F15: =IFERROR(__xludf.DUMMYFUNCTION("""COMPUTED_VALUE"""),46661.0) -> 46661
A16: =IFERROR(__xludf.DUMMYFUNCTION("""COMPUTED_VALUE"""),3250.0) -> 3250 | B16: =IFERROR(__xludf.DUMMYFUNCTION("""COMPUTED_VALUE"""),"02-Medellin") -> 02-Medellin | C16: =IFERROR(__xludf.DUMMYFUNCTION("""COMPUTED_VALUE"""),"PVS617") -> PVS617 | D16: =IFERROR(__xludf.DUMMYFUNCTION("""COMPUTED_VALUE"""),"FURGON FOTON 1030") -> FURGON FOTON 1030 | E16: =IFERROR(__xludf.DUMMYFUNCTION("""COMPUTED_VALUE"""),46295.0) -> 46295 | F16: =IFERROR(__xludf.DUMMYFUNCTION("""COMPUTED_VALUE"""),46661.0) -> 46661
A17: =IFERROR(__xludf.DUMMYFUNCTION("""COMPUTED_VALUE"""),3249.0) -> 3249 | B17: =IFERROR(__xludf.DUMMYFUNCTION("""COMPUTED_VALUE"""),"02-Medellin") -> 02-Medellin | C17: =IFERROR(__xludf.DUMMYFUNCTION("""COMPUTED_VALUE"""),"PVS616") -> PVS616 | D17: =IFERROR(__xludf.DUMMYFUNCTION("""COMPUTED_VALUE"""),"FURGON FOTON 1030") -> FURGON FOTON 1030 | E17: =IFERROR(__xludf.DUMMYFUNCTION("""COMPUTED_VALUE"""),46295.0) -> 46295 | F17: =IFERROR(__xludf.DUMMYFUNCTION("""COMPUTED_VALUE"""),46661.0) -> 46661
A18: =IFERROR(__xludf.DUMMYFUNCTION("""COMPUTED_VALUE"""),3247.0) -> 3247 | B18: =IFERROR(__xludf.DUMMYFUNCTION("""COMPUTED_VALUE"""),"02-Medellin") -> 02-Medellin | C18: =IFERROR(__xludf.DUMMYFUNCTION("""COMPUTED_VALUE"""),"PVS614") -> PVS614 | D18: =IFERROR(__xludf.DUMMYFUNCTION("""COMPUTED_VALUE"""),"FURGON FOTON 1030") -> FURGON FOTON 1030 | E18: =IFERROR(__xludf.DUMMYFUNCTION("""COMPUTED_VALUE"""),46295.0) -> 46295 | F18: =IFERROR(__xludf.DUMMYFUNCTION("""COMPUTED_VALUE"""),46661.0) -> 46661
A19: =IFERROR(__xludf.DUMMYFUNCTION("""COMPUTED_VALUE"""),3246.0) -> 3246 | B19: =IFERROR(__xludf.DUMMYFUNCTION("""COMPUTED_VALUE"""),"02-Medellin") -> 02-Medellin | C19: =IFERROR(__xludf.DUMMYFUNCTION("""COMPUTED_VALUE"""),"PVS613") -> PVS613 | D19: =IFERROR(__xludf.DUMMYFUNCTION("""COMPUTED_VALUE"""),"FURGON FOTON 1030") -> FURGON FOTON 1030 | E19: =IFERROR(__xludf.DUMMYFUNCTION("""COMPUTED_VALUE"""),46295.0) -> 46295 | F19: =IFERROR(__xludf.DUMMYFUNCTION("""COMPUTED_VALUE"""),46661.0) -> 46661
A20: =IFERROR(__xludf.DUMMYFUNCTION("""COMPUTED_VALUE"""),3241.0) -> 3241 | B20: =IFERROR(__xludf.DUMMYFUNCTION("""COMPUTED_VALUE"""),"02-Medellin") -> 02-Medellin | C20: =IFERROR(__xludf.DUMMYFUNCTION("""COMPUTED_VALUE"""),"PVS608") -> PVS608 | D20: =IFERROR(__xludf.DUMMYFUNCTION("""COMPUTED_VALUE"""),"FURGON FOTON 1030") -> FURGON FOTON 1030 | E20: =IFERROR(__xludf.DUMMYFUNCTION("""COMPUTED_VALUE"""),46295.0) -> 46295 | F20: =IFERROR(__xludf.DUMMYFUNCTION("""COMPUTED_VALUE"""),46661.0) -> 46661
A21: =IFERROR(__xludf.DUMMYFUNCTION("""COMPUTED_VALUE"""),3231.0) -> 3231 | B21: =IFERROR(__xludf.DUMMYFUNCTION("""COMPUTED_VALUE"""),"02-Medellin") -> 02-Medellin | C21: =IFERROR(__xludf.DUMMYFUNCTION("""COMPUTED_VALUE"""),"PVS598") -> PVS598 | D21: =IFERROR(__xludf.DUMMYFUNCTION("""COMPUTED_VALUE"""),"FURGON FOTON 1030") -> FURGON FOTON 1030 | E21: =IFERROR(__xludf.DUMMYFUNCTION("""COMPUTED_VALUE"""),46294.0) -> 46294 | F21: =IFERROR(__xludf.DUMMYFUNCTION("""COMPUTED_VALUE"""),46660.0) -> 46660
A22: =IFERROR(__xludf.DUMMYFUNCTION("""COMPUTED_VALUE"""),3219.0) -> 3219 | B22: =IFERROR(__xludf.DUMMYFUNCTION("""COMPUTED_VALUE"""),"02-Medellin") -> 02-Medellin | C22: =IFERROR(__xludf.DUMMYFUNCTION("""COMPUTED_VALUE"""),"PVS579") -> PVS579 | D22: =IFERROR(__xludf.DUMMYFUNCTION("""COMPUTED_VALUE"""),"FURGON FOTON 1030") -> FURGON FOTON 1030 | E22: =IFERROR(__xludf.DUMMYFUNCTION("""COMPUTED_VALUE"""),46287.0) -> 46287 | F22: =IFERROR(__xludf.DUMMYFUNCTION("""COMPUTED_VALUE"""),46654.0) -> 46654
A23: =IFERROR(__xludf.DUMMYFUNCTION("""COMPUTED_VALUE"""),3216.0) -> 3216 | B23: =IFERROR(__xludf.DUMMYFUNCTION("""COMPUTED_VALUE"""),"02-Medellin") -> 02-Medellin | C23: =IFERROR(__xludf.DUMMYFUNCTION("""COMPUTED_VALUE"""),"PVS576") -> PVS576 | D23: =IFERROR(__xludf.DUMMYFUNCTION("""COMPUTED_VALUE"""),"FURGON FOTON 1030") -> FURGON FOTON 1030 | E23: =IFERROR(__xludf.DUMMYFUNCTION("""COMPUTED_VALUE"""),46287.0) -> 46287 | F23: =IFERROR(__xludf.DUMMYFUNCTION("""COMPUTED_VALUE"""),46654.0) -> 46654
A24: =IFERROR(__xludf.DUMMYFUNCTION("""COMPUTED_VALUE"""),3215.0) -> 3215 | B24: =IFERROR(__xludf.DUMMYFUNCTION("""COMPUTED_VALUE"""),"02-Medellin") -> 02-Medellin | C24: =IFERROR(__xludf.DUMMYFUNCTION("""COMPUTED_VALUE"""),"PVS575") -> PVS575 | D24: =IFERROR(__xludf.DUMMYFUNCTION("""COMPUTED_VALUE"""),"FURGON FOTON 1030") -> FURGON FOTON 1030 | E24: =IFERROR(__xludf.DUMMYFUNCTION("""COMPUTED_VALUE"""),46287.0) -> 46287 | F24: =IFERROR(__xludf.DUMMYFUNCTION("""COMPUTED_VALUE"""),46654.0) -> 46654
A25: =IFERROR(__xludf.DUMMYFUNCTION("""COMPUTED_VALUE"""),3214.0) -> 3214 | B25: =IFERROR(__xludf.DUMMYFUNCTION("""COMPUTED_VALUE"""),"02-Medellin") -> 02-Medellin | C25: =IFERROR(__xludf.DUMMYFUNCTION("""COMPUTED_VALUE"""),"PVS574") -> PVS574 | D25: =IFERROR(__xludf.DUMMYFUNCTION("""COMPUTED_VALUE"""),"FURGON FOTON 1030") -> FURGON FOTON 1030 | E25: =IFERROR(__xludf.DUMMYFUNCTION("""COMPUTED_VALUE"""),46287.0) -> 46287 | F25: =IFERROR(__xludf.DUMMYFUNCTION("""COMPUTED_VALUE"""),46654.0) -> 46654
A26: =IFERROR(__xludf.DUMMYFUNCTION("""COMPUTED_VALUE"""),3213.0) -> 3213 | B26: =IFERROR(__xludf.DUMMYFUNCTION("""COMPUTED_VALUE"""),"02-Medellin") -> 02-Medellin | C26: =IFERROR(__xludf.DUMMYFUNCTION("""COMPUTED_VALUE"""),"PVS573") -> PVS573 | D26: =IFERROR(__xludf.DUMMYFUNCTION("""COMPUTED_VALUE"""),"FURGON FOTON 1030") -> FURGON FOTON 1030 | E26: =IFERROR(__xludf.DUMMYFUNCTION("""COMPUTED_VALUE"""),46287.0) -> 46287 | F26: =IFERROR(__xludf.DUMMYFUNCTION("""COMPUTED_VALUE"""),46654.0) -> 46654
A27: =IFERROR(__xludf.DUMMYFUNCTION("""COMPUTED_VALUE"""),3212.0) -> 3212 | B27: =IFERROR(__xludf.DUMMYFUNCTION("""COMPUTED_VALUE"""),"02-Medellin") -> 02-Medellin | C27: =IFERROR(__xludf.DUMMYFUNCTION("""COMPUTED_VALUE"""),"PVS572") -> PVS572 | D27: =IFERROR(__xludf.DUMMYFUNCTION("""COMPUTED_VALUE"""),"FURGON FOTON 1030") -> FURGON FOTON 1030 | E27: =IFERROR(__xludf.DUMMYFUNCTION("""COMPUTED_VALUE"""),46287.0) -> 46287 | F27: =IFERROR(__xludf.DUMMYFUNCTION("""COMPUTED_VALUE"""),46654.0) -> 46654
A28: =IFERROR(__xludf.DUMMYFUNCTION("""COMPUTED_VALUE"""),3210.0) -> 3210 | B28: =IFERROR(__xludf.DUMMYFUNCTION("""COMPUTED_VALUE"""),"02-Medellin") -> 02-Medellin | C28: =IFERROR(__xludf.DUMMYFUNCTION("""COMPUTED_VALUE"""),"PVS567") -> PVS567 | D28: =IFERROR(__xludf.DUMMYFUNCTION("""COMPUTED_VALUE"""),"FURGON FOTON 1030") -> FURGON FOTON 1030 | E28: =IFERROR(__xludf.DUMMYFUNCTION("""COMPUTED_VALUE"""),46282.0) -> 46282 | F28: =IFERROR(__xludf.DUMMYFUNCTION("""COMPUTED_VALUE"""),46648.0) -> 46648
A29: =IFERROR(__xludf.DUMMYFUNCTION("""COMPUTED_VALUE"""),3209.0) -> 3209 | B29: =IFERROR(__xludf.DUMMYFUNCTION("""COMPUTED_VALUE"""),"02-Medellin") -> 02-Medellin | C29: =IFERROR(__xludf.DUMMYFUNCTION("""COMPUTED_VALUE"""),"PVS566") -> PVS566 | D29: =IFERROR(__xludf.DUMMYFUNCTION("""COMPUTED_VALUE"""),"FURGON FOTON 1030") -> FURGON FOTON 1030
A30: =IFERROR(__xludf.DUMMYFUNCTION("""COMPUTED_VALUE"""),3202.0) -> 3202 | B30: =IFERROR(__xludf.DUMMYFUNCTION("""COMPUTED_VALUE"""),"02-Medellin") -> 02-Medellin | C30: =IFERROR(__xludf.DUMMYFUNCTION("""COMPUTED_VALUE"""),"PVS559") -> PVS559 | D30: =IFERROR(__xludf.DUMMYFUNCTION("""COMPUTED_VALUE"""),"FURGON FOTON 1030") -> FURGON FOTON 1030 | E30: =IFERROR(__xludf.DUMMYFUNCTION("""COMPUTED_VALUE"""),46282.0) -> 46282 | F30: =IFERROR(__xludf.DUMMYFUNCTION("""COMPUTED_VALUE"""),46653.0) -> 46653
A31: =IFERROR(__xludf.DUMMYFUNCTION("""COMPUTED_VALUE"""),3201.0) -> 3201 | B31: =IFERROR(__xludf.DUMMYFUNCTION("""COMPUTED_VALUE"""),"02-Medellin") -> 02-Medellin | C31: =IFERROR(__xludf.DUMMYFUNCTION("""COMPUTED_VALUE"""),"PVS558") -> PVS558 | D31: =IFERROR(__xludf.DUMMYFUNCTION("""COMPUTED_VALUE"""),"FURGON FOTON 1030") -> FURGON FOTON 1030 | E31: =IFERROR(__xludf.DUMMYFUNCTION("""COMPUTED_VALUE"""),46282.0) -> 46282 | F31: =IFERROR(__xludf.DUMMYFUNCTION("""COMPUTED_VALUE"""),46654.0) -> 46654
A32: =IFERROR(__xludf.DUMMYFUNCTION("""COMPUTED_VALUE"""),3200.0) -> 3200 | B32: =IFERROR(__xludf.DUMMYFUNCTION("""COMPUTED_VALUE"""),"02-Medellin") -> 02-Medellin | C32: =IFERROR(__xludf.DUMMYFUNCTION("""COMPUTED_VALUE"""),"PVS557") -> PVS557 | D32: =IFERROR(__xludf.DUMMYFUNCTION("""COMPUTED_VALUE"""),"FURGON FOTON 1030") -> FURGON FOTON 1030 | E32: =IFERROR(__xludf.DUMMYFUNCTION("""COMPUTED_VALUE"""),46282.0) -> 46282 | F32: =IFERROR(__xludf.DUMMYFUNCTION("""COMPUTED_VALUE"""),46654.0) -> 46654
A33: =IFERROR(__xludf.DUMMYFUNCTION("""COMPUTED_VALUE"""),3198.0) -> 3198 | B33: =IFERROR(__xludf.DUMMYFUNCTION("""COMPUTED_VALUE"""),"31-Copacabana") -> 31-Copacabana | C33: =IFERROR(__xludf.DUMMYFUNCTION("""COMPUTED_VALUE"""),"PVS555") -> PVS555 | D33: =IFERROR(__xludf.DUMMYFUNCTION("""COMPUTED_VALUE"""),"FURGON FOTON 1030") -> FURGON FOTON 1030 | E33: =IFERROR(__xludf.DUMMYFUNCTION("""COMPUTED_VALUE"""),46282.0) -> 46282 | F33: =IFERROR(__xludf.DUMMYFUNCTION("""COMPUTED_VALUE"""),46654.0) -> 46654
A34: =IFERROR(__xludf.DUMMYFUNCTION("""COMPUTED_VALUE"""),3197.0) -> 3197 | B34: =IFERROR(__xludf.DUMMYFUNCTION("""COMPUTED_VALUE"""),"02-Medellin") -> 02-Medellin | C34: =IFERROR(__xludf.DUMMYFUNCTION("""COMPUTED_VALUE"""),"PVS554") -> PVS554 | D34: =IFERROR(__xludf.DUMMYFUNCTION("""COMPUTED_VALUE"""),"FURGON FOTON 1030") -> FURGON FOTON 1030 | E34: =IFERROR(__xludf.DUMMYFUNCTION("""COMPUTED_VALUE"""),46282.0) -> 46282 | F34: =IFERROR(__xludf.DUMMYFUNCTION("""COMPUTED_VALUE"""),46653.0) -> 46653
A35: =IFERROR(__xludf.DUMMYFUNCTION("""COMPUTED_VALUE"""),2927.0) -> 2927 | B35: =IFERROR(__xludf.DUMMYFUNCTION("""COMPUTED_VALUE"""),"02-Medellin") -> 02-Medellin | C35: =IFERROR(__xludf.DUMMYFUNCTION("""COMPUTED_VALUE"""),"NNZ367") -> NNZ367 | D35: =IFERROR(__xludf.DUMMYFUNCTION("""COMPUTED_VALUE"""),"FURGON JMC 1054 E VI") -> FURGON JMC 1054 E VI | E35: =IFERROR(__xludf.DUMMYFUNCTION("""COMPUTED_VALUE"""),46316.0) -> 46316 | F35: =IFERROR(__xludf.DUMMYFUNCTION("""COMPUTED_VALUE"""),46318.0) -> 46318
A36: =IFERROR(__xludf.DUMMYFUNCTION("""COMPUTED_VALUE"""),2926.0) -> 2926 | B36: =IFERROR(__xludf.DUMMYFUNCTION("""COMPUTED_VALUE"""),"31-Copacabana") -> 31-Copacabana | C36: =IFERROR(__xludf.DUMMYFUNCTION("""COMPUTED_VALUE"""),"NNZ366") -> NNZ366 | D36: =IFERROR(__xludf.DUMMYFUNCTION("""COMPUTED_VALUE"""),"FURGON JMC 1054 E VI") -> FURGON JMC 1054 E VI | E36: =IFERROR(__xludf.DUMMYFUNCTION("""COMPUTED_VALUE"""),46316.0) -> 46316 | F36: =IFERROR(__xludf.DUMMYFUNCTION("""COMPUTED_VALUE"""),46318.0) -> 46318
A37: =IFERROR(__xludf.DUMMYFUNCTION("""COMPUTED_VALUE"""),2925.0) -> 2925 | B37: =IFERROR(__xludf.DUMMYFUNCTION("""COMPUTED_VALUE"""),"02-Medellin") -> 02-Medellin | C37: =IFERROR(__xludf.DUMMYFUNCTION("""COMPUTED_VALUE"""),"NNZ365") -> NNZ365 | D37: =IFERROR(__xludf.DUMMYFUNCTION("""COMPUTED_VALUE"""),"FURGON JMC 1054 E VI") -> FURGON JMC 1054 E VI | E37: =IFERROR(__xludf.DUMMYFUNCTION("""COMPUTED_VALUE"""),46316.0) -> 46316 | F37: =IFERROR(__xludf.DUMMYFUNCTION("""COMPUTED_VALUE"""),46318.0) -> 46318
A38: =IFERROR(__xludf.DUMMYFUNCTION("""COMPUTED_VALUE"""),2924.0) -> 2924 | B38: =IFERROR(__xludf.DUMMYFUNCTION("""COMPUTED_VALUE"""),"02-Medellin") -> 02-Medellin | C38: =IFERROR(__xludf.DUMMYFUNCTION("""COMPUTED_VALUE"""),"NNZ364") -> NNZ364 | D38: =IFERROR(__xludf.DUMMYFUNCTION("""COMPUTED_VALUE"""),"FURGON JMC 1054 E VI") -> FURGON JMC 1054 E VI | E38: =IFERROR(__xludf.DUMMYFUNCTION("""COMPUTED_VALUE"""),46316.0) -> 46316 | F38: =IFERROR(__xludf.DUMMYFUNCTION("""COMPUTED_VALUE"""),46318.0) -> 46318
A39: =IFERROR(__xludf.DUMMYFUNCTION("""COMPUTED_VALUE"""),2923.0) -> 2923 | B39: =IFERROR(__xludf.DUMMYFUNCTION("""COMPUTED_VALUE"""),"BULTOS") -> BULTOS | C39: =IFERROR(__xludf.DUMMYFUNCTION("""COMPUTED_VALUE"""),"NNZ363") -> NNZ363 | D39: =IFERROR(__xludf.DUMMYFUNCTION("""COMPUTED_VALUE"""),"FURGON JMC 1054 E VI") -> FURGON JMC 1054 E VI | E39: =IFERROR(__xludf.DUMMYFUNCTION("""COMPUTED_VALUE"""),46316.0) -> 46316 | F39: =IFERROR(__xludf.DUMMYFUNCTION("""COMPUTED_VALUE"""),46318.0) -> 46318
A40: =IFERROR(__xludf.DUMMYFUNCTION("""COMPUTED_VALUE"""),2922.0) -> 2922 | B40: =IFERROR(__xludf.DUMMYFUNCTION("""COMPUTED_VALUE"""),"02-Medellin") -> 02-Medellin | C40: =IFERROR(__xludf.DUMMYFUNCTION("""COMPUTED_VALUE"""),"NNZ362") -> NNZ362 | D40: =IFERROR(__xludf.DUMMYFUNCTION("""COMPUTED_VALUE"""),"FURGON JMC 1054 E VI") -> FURGON JMC 1054 E VI | E40: =IFERROR(__xludf.DUMMYFUNCTION("""COMPUTED_VALUE"""),46316.0) -> 46316 | F40: =IFERROR(__xludf.DUMMYFUNCTION("""COMPUTED_VALUE"""),46318.0) -> 46318
...

Sheet Q LUB
A1: Móvil | B1: Linea Vehículo | C1: Terminal | D1: Frecuencia KM | E1: Frecuencia Días | F1: Diferencia Días | G1: Diferencia KMs | H1: Fecha de Terminación de la Orden | I1: Fecha Actual | J1: Estado | K1: Orden de Trabajo | L1: KMs último LUB | M1: Última Ubicación
A2: 451 | B2: Tractomula International Eagle 9400 | C2: 98. Ruta Nacional | D2: 30000 | E2: 120 | F2: 1 | G2: 0 | H2: 46211 | I2: 46212 | J2: Vigente | K2: 1162175 | L2: 2235015.8 | M2: 2. Medellin
A3: 461 | B3: Tractomula International Eagle 9400 | C3: 2. Medellin | D3: 30000 | E3: 180 | F3: 119 | G3: 9761.5 | H3: 46093 | I3: 46212 | J3: Vigente | K3: 1152495 | L3: 1275107.8 | M3: 31. Copacabana
A4: 463 | B4: Tractomula International Eagle 9400 | C4: 98. Ruta Nacional | D4: 30000 | E4: 120 | F4: 104 | G4: 29578.6 | H4: 46108 | I4: 46212 | J4: Vigente | K4: 1154436 | L4: 1831940.3 | M4: 2. Medellin
A5: 464 | B5: Tractomula International Eagle 9400 | C5: 2. Medellin | D5: 30000 | E5: 120 | F5: 113 | G5: 6353.4 | H5: 46099 | I5: 46212 | J5: Vigente | K5: 1153642 | L5: 1495074.8 | M5: 24. Rionegro
A6: 467 | B6: Tractomula International Eagle 9400 | C6: 98. Ruta Nacional | D6: 30000 | E6: 120 | F6: 28 | G6: 10279.9 | H6: 46184 | I6: 46212 | J6: Vigente | K6: 1161770 | L6: 1648403.4 | M6: 1. Bogota
A7: 471 | B7: Tractomula International Eagle 9400 | C7: 98. Ruta Nacional | D7: 30000 | E7: 120 | F7: 121 | G7: 40886.2 | H7: 46091 | I7: 46212 | J7: Pasado | K7: 1152656 | L7: 1664739.1 | M7: 6. Bucaramanga
A8: 472 | B8: Tractomula International Eagle 9400 | C8: 2. Medellin | D8: 30000 | E8: 180 | F8: 66 | G8: 7494.5 | H8: 46146 | I8: 46212 | J8: Vigente | K8: 1158352 | L8: 1590122.9 | M8: 24. Rionegro
A9: 473 | B9: Tractomula International Eagle 9400 | C9: 98. Ruta Nacional | D9: 30000 | E9: 120 | F9: 93 | G9: 895 | H9: 46119 | I9: 46212 | J9: Vigente | K9: 1155268 | L9: 1701870.4 | M9: 2. Medellin
A10: 475 | B10: Tractomula International Eagle 9400 | C10: 98. Ruta Nacional | D10: 30000 | E10: 120 | F10: 80 | G10: 17594.3 | H10: 46132 | I10: 46212 | J10: Vigente | K10: 1156745 | L10: 1624460.2 | M10: 4. Pereira
A11: 477 | B11: Tractomula International Eagle 9400 | C11: 98. Ruta Nacional | D11: 30000 | E11: 120 | F11: 35 | G11: 8993.9 | H11: 46177 | I11: 46212 | J11: Vigente | K11: 1161596 | L11: 1587565.9 | M11: 1. Bogota
A12: 478 | B12: Tractomula International Eagle 9400 | C12: 98. Ruta Nacional | D12: 30000 | E12: 120 | F12: 28 | G12: 9439.1 | H12: 46184 | I12: 46212 | J12: Vigente | K12: 1161769 | L12: 1461686.1 | M12: 1. Bogota
A13: 481 | B13: Tractomula International Eagle 9400 | C13: 2. Medellin | D13: 30000 | E13: 180 | F13: 176 | G13: 17198.2 | H13: 46036 | I13: 46212 | J13: Vigente | K13: 1146210 | L13: 1128050.1 | M13: 2. Medellin
... A435: 3284 | B435: Furgon Foton 1030 | C435: 2. Medellin | D435: 5000 | E435: 180 | F435: 134 | G435: 5187 | H435: 46078 | I435: 46212 | J435: Pasado | K435: 1151104 | L435: 4559 | M435: Sin Última Ubicación
A436: 222129 | B436: Tractomula Dongfeng Dfh4250c7 | C436: 98. Ruta Nacional | D436: 0 | E436: 0 | F436: 0 | G436: 0 | H436: - | I436: 46212 | J436: Pendiente | K436: - | L436: 0 | M436: 31. Copacabana
A437: 222134 | B437: Van Citroen Berlingo | C437: 2. Medellin | D437: 0 | E437: 0 | F437: 0 | G437: 0 | H437: - | I437: 46212 | J437: Pendiente | K437: - | L437: 0 | M437: Sin Última Ubicación

Sheet BD LUB
A1: MÓVIL | B1: DESCRIPCIÓN | C1: POBLACIÓN | D1: F ULTIMA LUBRICACIÒN MOTOR | E1: TIEMPO DEL ACEITE | F1: KM DEL ACEITE | G1: FRECUENCIA DIAS | H1: FRECUENCIA KM | I1: PRIORIDAD TIEMPO | J1: PRIORIDAD KM | K1: ESTADO TIEMPO | L1: ESTADO KM | M1: TIEMPO DE PRÓXIMO | N1: KM DE PRÓXIMO
A2: ='RECURSO ACTUAL'!A2 -> 3284 | B2: ='RECURSO ACTUAL'!F2 -> 46668 | C2: ='RECURSO ACTUAL'!B2 -> 02-Medellin | D2: =VLOOKUP(A2,'Q LUB'!A:L,8,FALSE) -> 46078 | E2: =ABS(D2-TODAY()) -> 138 | F2: =VLOOKUP(A2,'Q LUB'!A:L,7,FALSE) -> 5187 | G2: =VLOOKUP(A2,'Q LUB'!A:L,5,FALSE) -> 180 | H2: =VLOOKUP(A2,'Q LUB'!A:L,4,FALSE) -> 5000 | I2: =G2-E2 -> 42 | J2: =H2-F2 -> -187 | K2: =IF(E2>G2,"PASADO",(IF(AND(E2>=G2-$M$2,E2<=G2),"PRÓXIMO","VIGENTE"))) -> VIGENTE | L2: =IF(F2>H2,"PASADO",(IF(AND(F2>=H2-$N$2,F2<=H2),"PRÓXIMO","VIGENTE"))) -> PASADO | M2: 10 | N2: 700
A3: ='RECURSO ACTUAL'!A3 -> 3283 | B3: ='RECURSO ACTUAL'!F3 -> 46668 | C3: ='RECURSO ACTUAL'!B3 -> 02-Medellin | D3: =VLOOKUP(A3,'Q LUB'!A:L,8,FALSE) -> 46062 | E3: =ABS(D3-TODAY()) -> 154 | F3: =VLOOKUP(A3,'Q LUB'!A:L,7,FALSE) -> 6291 | G3: =VLOOKUP(A3,'Q LUB'!A:L,5,FALSE) -> 180 | H3: =VLOOKUP(A3,'Q LUB'!A:L,4,FALSE) -> 5000 | I3: =G3-E3 -> 26 | J3: =H3-F3 -> -1291 | K3: =IF(E3>G3,"PASADO",(IF(AND(E3>=G3-$M$2,E3<=G3),"PRÓXIMO","VIGENTE"))) -> VIGENTE | L3: =IF(F3>H3,"PASADO",(IF(AND(F3>=H3-$N$2,F3<=H3),"PRÓXIMO","VIGENTE"))) -> PASADO
A4: ='RECURSO ACTUAL'!A4 -> 3282 | B4: ='RECURSO ACTUAL'!F4 -> 46668 | C4: ='RECURSO ACTUAL'!B4 -> 02-Medellin | D4: =VLOOKUP(A4,'Q LUB'!A:L,8,FALSE) -> 46086 | E4: =ABS(D4-TODAY()) -> 130 | F4: =VLOOKUP(A4,'Q LUB'!A:L,7,FALSE) -> 5790 | G4: =VLOOKUP(A4,'Q LUB'!A:L,5,FALSE) -> 180 | H4: =VLOOKUP(A4,'Q LUB'!A:L,4,FALSE) -> 5000 | I4: =G4-E4 -> 50 | J4: =H4-F4 -> -790 | K4: =IF(E4>G4,"PASADO",(IF(AND(E4>=G4-$M$2,E4<=G4),"PRÓXIMO","VIGENTE"))) -> VIGENTE | L4: =IF(F4>H4,"PASADO",(IF(AND(F4>=H4-$N$2,F4<=H4),"PRÓXIMO","VIGENTE"))) -> PASADO
A5: ='RECURSO ACTUAL'!A5 -> 3281 | B5: ='RECURSO ACTUAL'!F5 -> 46668 | C5: ='RECURSO ACTUAL'!B5 -> 02-Medellin | D5: =VLOOKUP(A5,'Q LUB'!A:L,8,FALSE) -> 46078 | E5: =ABS(D5-TODAY()) -> 138 | F5: =VLOOKUP(A5,'Q LUB'!A:L,7,FALSE) -> 5415 | G5: =VLOOKUP(A5,'Q LUB'!A:L,5,FALSE) -> 180 | H5: =VLOOKUP(A5,'Q LUB'!A:L,4,FALSE) -> 5000 | I5: =G5-E5 -> 42 | J5: =H5-F5 -> -415 | K5: =IF(E5>G5,"PASADO",(IF(AND(E5>=G5-$M$2,E5<=G5),"PRÓXIMO","VIGENTE"))) -> VIGENTE | L5: =IF(F5>H5,"PASADO",(IF(AND(F5>=H5-$N$2,F5<=H5),"PRÓXIMO","VIGENTE"))) -> PASADO
A6: ='RECURSO ACTUAL'!A6 -> 3280 | B6: ='RECURSO ACTUAL'!F6 -> 46668 | C6: ='RECURSO ACTUAL'!B6 -> 02-Medellin | D6: =VLOOKUP(A6,'Q LUB'!A:L,8,FALSE) -> 46087 | E6: =ABS(D6-TODAY()) -> 129 | F6: =VLOOKUP(A6,'Q LUB'!A:L,7,FALSE) -> 5847 | G6: =VLOOKUP(A6,'Q LUB'!A:L,5,FALSE) -> 180 | H6: =VLOOKUP(A6,'Q LUB'!A:L,4,FALSE) -> 5000 | I6: =G6-E6 -> 51 | J6: =H6-F6 -> -847 | K6: =IF(E6>G6,"PASADO",(IF(AND(E6>=G6-$M$2,E6<=G6),"PRÓXIMO","VIGENTE"))) -> VIGENTE | L6: =IF(F6>H6,"PASADO",(IF(AND(F6>=H6-$N$2,F6<=H6),"PRÓXIMO","VIGENTE"))) -> PASADO
A7: ='RECURSO ACTUAL'!A7 -> 3279 | B7: ='RECURSO ACTUAL'!F7 -> 46668 | C7: ='RECURSO ACTUAL'!B7 -> 02-Medellin | D7: =VLOOKUP(A7,'Q LUB'!A:L,8,FALSE) -> 46126 | E7: =ABS(D7-TODAY()) -> 90 | F7: =VLOOKUP(A7,'Q LUB'!A:L,7,FALSE) -> 3342 | G7: =VLOOKUP(A7,'Q LUB'!A:L,5,FALSE) -> 180 | H7: =VLOOKUP(A7,'Q LUB'!A:L,4,FALSE) -> 5000 | I7: =G7-E7 -> 90 | J7: =H7-F7 -> 1658 | K7: =IF(E7>G7,"PASADO",(IF(AND(E7>=G7-$M$2,E7<=G7),"PRÓXIMO","VIGENTE"))) -> VIGENTE | L7: =IF(F7>H7,"PASADO",(IF(AND(F7>=H7-$N$2,F7<=H7),"PRÓXIMO","VIGENTE"))) -> VIGENTE
A8: ='RECURSO ACTUAL'!A8 -> 3278 | B8: ='RECURSO ACTUAL'!F8 -> 46668 | C8: ='RECURSO ACTUAL'!B8 -> 02-Medellin | D8: =VLOOKUP(A8,'Q LUB'!A:L,8,FALSE) -> 46150 | E8: =ABS(D8-TODAY()) -> 66 | F8: =VLOOKUP(A8,'Q LUB'!A:L,7,FALSE) -> 2440 | G8: =VLOOKUP(A8,'Q LUB'!A:L,5,FALSE) -> 180 | H8: =VLOOKUP(A8,'Q LUB'!A:L,4,FALSE) -> 5000 | I8: =G8-E8 -> 114 | J8: =H8-F8 -> 2560 | K8: =IF(E8>G8,"PASADO",(IF(AND(E8>=G8-$M$2,E8<=G8),"PRÓXIMO","VIGENTE"))) -> VIGENTE | L8: =IF(F8>H8,"PASADO",(IF(AND(F8>=H8-$N$2,F8<=H8),"PRÓXIMO","VIGENTE"))) -> VIGENTE
A9: ='RECURSO ACTUAL'!A9 -> 3275 | B9: ='RECURSO ACTUAL'!F9 -> 46668 | C9: ='RECURSO ACTUAL'!B9 -> 02-Medellin | D9: =VLOOKUP(A9,'Q LUB'!A:L,8,FALSE) -> 46070 | E9: =ABS(D9-TODAY()) -> 146 | F9: =VLOOKUP(A9,'Q LUB'!A:L,7,FALSE) -> 4607 | G9: =VLOOKUP(A9,'Q LUB'!A:L,5,FALSE) -> 180 | H9: =VLOOKUP(A9,'Q LUB'!A:L,4,FALSE) -> 5000 | I9: =G9-E9 -> 34 | J9: =H9-F9 -> 393 | K9: =IF(E9>G9,"PASADO",(IF(AND(E9>=G9-$M$2,E9<=G9),"PRÓXIMO","VIGENTE"))) -> VIGENTE | L9: =IF(F9>H9,"PASADO",(IF(AND(F9>=H9-$N$2,F9<=H9),"PRÓXIMO","VIGENTE"))) -> PRÓXIMO
A10: ='RECURSO ACTUAL'!A10 -> 3273 | B10: ='RECURSO ACTUAL'!F10 -> 46668 | C10: ='RECURSO ACTUAL'!B10 -> 02-Medellin | D10: =VLOOKUP(A10,'Q LUB'!A:L,8,FALSE) -> 46070 | E10: =ABS(D10-TODAY()) -> 146 | F10: =VLOOKUP(A10,'Q LUB'!A:L,7,FALSE) -> 4563 | G10: =VLOOKUP(A10,'Q LUB'!A:L,5,FALSE) -> 180 | H10: =VLOOKUP(A10,'Q LUB'!A:L,4,FALSE) -> 5000 | I10: =G10-E10 -> 34 | J10: =H10-F10 -> 437 | K10: =IF(E10>G10,"PASADO",(IF(AND(E10>=G10-$M$2,E10<=G10),"PRÓXIMO","VIGENTE"))) -> VIGENTE | L10: =IF(F10>H10,"PASADO",(IF(AND(F10>=H10-$N$2,F10<=H10),"PRÓXIMO","VIGENTE"))) -> PRÓXIMO
A11: ='RECURSO ACTUAL'!A11 -> 3271 | B11: ='RECURSO ACTUAL'!F11 -> 46668 | C11: ='RECURSO ACTUAL'!B11 -> 02-Medellin | D11: =VLOOKUP(A11,'Q LUB'!A:L,8,FALSE) -> 46097 | E11: =ABS(D11-TODAY()) -> 119 | F11: =VLOOKUP(A11,'Q LUB'!A:L,7,FALSE) -> 4954 | G11: =VLOOKUP(A11,'Q LUB'!A:L,5,FALSE) -> 180 | H11: =VLOOKUP(A11,'Q LUB'!A:L,4,FALSE) -> 5000 | I11: =G11-E11 -> 61 | J11: =H11-F11 -> 46 | K11: =IF(E11>G11,"PASADO",(IF(AND(E11>=G11-$M$2,E11<=G11),"PRÓXIMO","VIGENTE"))) -> VIGENTE | L11: =IF(F11>H11,"PASADO",(IF(AND(F11>=H11-$N$2,F11<=H11),"PRÓXIMO","VIGENTE"))) -> PRÓXIMO
A12: ='RECURSO ACTUAL'!A12 -> 3264 | B12: ='RECURSO ACTUAL'!F12 -> 46668 | C12: ='RECURSO ACTUAL'!B12 -> 02-Medellin | D12: =VLOOKUP(A12,'Q LUB'!A:L,8,FALSE) -> 46106 | E12: =ABS(D12-TODAY()) -> 110 | F12: =VLOOKUP(A12,'Q LUB'!A:L,7,FALSE) -> 3474 | G12: =VLOOKUP(A12,'Q LUB'!A:L,5,FALSE) -> 180 | H12: =VLOOKUP(A12,'Q LUB'!A:L,4,FALSE) -> 5000 | I12: =G12-E12 -> 70 | J12: =H12-F12 -> 1526 | K12: =IF(E12>G12,"PASADO",(IF(AND(E12>=G12-$M$2,E12<=G12),"PRÓXIMO","VIGENTE"))) -> VIGENTE | L12: =IF(F12>H12,"PASADO",(IF(AND(F12>=H12-$N$2,F12<=H12),"PRÓXIMO","VIGENTE"))) -> VIGENTE
A13: ='RECURSO ACTUAL'!A13 -> 3256 | B13: ='RECURSO ACTUAL'!F13 -> 46668 | C13: ='RECURSO ACTUAL'!B13 -> 02-Medellin | D13: =VLOOKUP(A13,'Q LUB'!A:L,8,FALSE) -> 46128 | E13: =ABS(D13-TODAY()) -> 88 | F13: =VLOOKUP(A13,'Q LUB'!A:L,7,FALSE) -> 3397 | G13: =VLOOKUP(A13,'Q LUB'!A:L,5,FALSE) -> 180 | H13: =VLOOKUP(A13,'Q LUB'!A:L,4,FALSE) -> 5000 | I13: =G13-E13 -> 92 | J13: =H13-F13 -> 1603 | K13: =IF(E13>G13,"PASADO",(IF(AND(E13>=G13-$M$2,E13<=G13),"PRÓXIMO","VIGENTE"))) -> VIGENTE | L13: =IF(F13>H13,"PASADO",(IF(AND(F13>=H13-$N$2,F13<=H13),"PRÓXIMO","VIGENTE"))) -> VIGENTE
A14: ='RECURSO ACTUAL'!A14 -> 3252 | B14: ='RECURSO ACTUAL'!F14 -> 46661 | C14: ='RECURSO ACTUAL'!B14 -> 24-Rionegro | D14: =VLOOKUP(A14,'Q LUB'!A:L,8,FALSE) -> 46161 | E14: =ABS(D14-TODAY()) -> 55 | F14: =VLOOKUP(A14,'Q LUB'!A:L,7,FALSE) -> 2288 | G14: =VLOOKUP(A14,'Q LUB'!A:L,5,FALSE) -> 180 | H14: =VLOOKUP(A14,'Q LUB'!A:L,4,FALSE) -> 5000 | I14: =G14-E14 -> 125 | J14: =H14-F14 -> 2712 | K14: =IF(E14>G14,"PASADO",(IF(AND(E14>=G14-$M$2,E14<=G14),"PRÓXIMO","VIGENTE"))) -> VIGENTE | L14: =IF(F14>H14,"PASADO",(IF(AND(F14>=H14-$N$2,F14<=H14),"PRÓXIMO","VIGENTE"))) -> VIGENTE
... A28: ='RECURSO ACTUAL'!A28 -> 3210 | B28: ='RECURSO ACTUAL'!F28 -> 46648 | C28: ='RECURSO ACTUAL'!B28 -> 02-Medellin | D28: =VLOOKUP(A28,'Q LUB'!A:L,8,FALSE) -> 46147 | E28: =ABS(D28-TODAY()) -> 69 | F28: =VLOOKUP(A28,'Q LUB'!A:L,7,FALSE) -> 2955 | G28: =VLOOKUP(A28,'Q LUB'!A:L,5,FALSE) -> 180 | H28: =VLOOKUP(A28,'Q LUB'!A:L,4,FALSE) -> 5000 | I28: =G28-E28 -> 111 | J28: =H28-F28 -> 2045 | K28: =IF(E28>G28,"PASADO",(IF(AND(E28>=G28-$M$2,E28<=G28),"PRÓXIMO","VIGENTE"))) -> VIGENTE | L28: =IF(F28>H28,"PASADO",(IF(AND(F28>=H28-$N$2,F28<=H28),"PRÓXIMO","VIGENTE"))) -> VIGENTE
A29: ='RECURSO ACTUAL'!A30 -> 3202 | B29: ='RECURSO ACTUAL'!F30 -> 46653 | C29: ='RECURSO ACTUAL'!B30 -> 02-Medellin | D29: =VLOOKUP(A29,'Q LUB'!A:L,8,FALSE) -> 46112 | E29: =ABS(D29-TODAY()) -> 104 | F29: =VLOOKUP(A29,'Q LUB'!A:L,7,FALSE) -> 5377 | G29: =VLOOKUP(A29,'Q LUB'!A:L,5,FALSE) -> 180 | H29: =VLOOKUP(A29,'Q LUB'!A:L,4,FALSE) -> 5000 | I29: =G29-E29 -> 76 | J29: =H29-F29 -> -377 | K29: =IF(E29>G29,"PASADO",(IF(AND(E29>=G29-$M$2,E29<=G29),"PRÓXIMO","VIGENTE"))) -> VIGENTE | L29: =IF(F29>H29,"PASADO",(IF(AND(F29>=H29-$N$2,F29<=H29),"PRÓXIMO","VIGENTE"))) -> PASADO
A30: ='RECURSO ACTUAL'!A31 -> 3201 | B30: ='RECURSO ACTUAL'!F31 -> 46654 | C30: ='RECURSO ACTUAL'!B31 -> 02-Medellin | D30: =VLOOKUP(A30,'Q LUB'!A:L,8,FALSE) -> 46097 | E30: =ABS(D30-TODAY()) -> 119 | F30: =VLOOKUP(A30,'Q LUB'!A:L,7,FALSE) -> 3840 | G30: =VLOOKUP(A30,'Q LUB'!A:L,5,FALSE) -> 180 | H30: =VLOOKUP(A30,'Q LUB'!A:L,4,FALSE) -> 5000 | I30: =G30-E30 -> 61 | J30: =H30-F30 -> 1160 | K30: =IF(E30>G30,"PASADO",(IF(AND(E30>=G30-$M$2,E30<=G30),"PRÓXIMO","VIGENTE"))) -> VIGENTE | L30: =IF(F30>H30,"PASADO",(IF(AND(F30>=H30-$N$2,F30<=H30),"PRÓXIMO","VIGENTE"))) -> VIGENTE
A31: ='RECURSO ACTUAL'!A32 -> 3200 | B31: ='RECURSO ACTUAL'!F32 -> 46654 | C31: ='RECURSO ACTUAL'!B32 -> 02-Medellin | D31: =VLOOKUP(A31,'Q LUB'!A:L,8,FALSE) -> 46091 | E31: =ABS(D31-TODAY()) -> 125 | F31: =VLOOKUP(A31,'Q LUB'!A:L,7,FALSE) -> 4976 | G31: =VLOOKUP(A31,'Q LUB'!A:L,5,FALSE) -> 180 | H31: =VLOOKUP(A31,'Q LUB'!A:L,4,FALSE) -> 5000 | I31: =G31-E31 -> 55 | J31: =H31-F31 -> 24 | K31: =IF(E31>G31,"PASADO",(IF(AND(E31>=G31-$M$2,E31<=G31),"PRÓXIMO","VIGENTE"))) -> VIGENTE | L31: =IF(F31>H31,"PASADO",(IF(AND(F31>=H31-$N$2,F31<=H31),"PRÓXIMO","VIGENTE"))) -> PRÓXIMO
A32: ='RECURSO ACTUAL'!A33 -> 3198 | B32: ='RECURSO ACTUAL'!F33 -> 46654 | C32: ='RECURSO ACTUAL'!B33 -> 31-Copacabana | D32: =VLOOKUP(A32,'Q LUB'!A:L,8,FALSE) -> 46062 | E32: =ABS(D32-TODAY()) -> 154 | F32: =VLOOKUP(A32,'Q LUB'!A:L,7,FALSE) -> 5962 | G32: =VLOOKUP(A32,'Q LUB'!A:L,5,FALSE) -> 180 | H32: =VLOOKUP(A32,'Q LUB'!A:L,4,FALSE) -> 5000 | I32: =G32-E32 -> 26 | J32: =H32-F32 -> -962 | K32: =IF(E32>G32,"PASADO",(IF(AND(E32>=G32-$M$2,E32<=G32),"PRÓXIMO","VIGENTE"))) -> VIGENTE | L32: =IF(F32>H32,"PASADO",(IF(AND(F32>=H32-$N$2,F32<=H32),"PRÓXIMO","VIGENTE"))) -> PASADO
A33: ='RECURSO ACTUAL'!A34 -> 3197 | B33: ='RECURSO ACTUAL'!F34 -> 46653 | C33: ='RECURSO ACTUAL'!B34 -> 02-Medellin | D33: =VLOOKUP(A33,'Q LUB'!A:L,8,FALSE) -> 46078 | E33: =ABS(D33-TODAY()) -> 138 | F33: =VLOOKUP(A33,'Q LUB'!A:L,7,FALSE) -> 4369 | G33: =VLOOKUP(A33,'Q LUB'!A:L,5,FALSE) -> 180 | H33: =VLOOKUP(A33,'Q LUB'!A:L,4,FALSE) -> 5000 | I33: =G33-E33 -> 42 | J33: =H33-F33 -> 631 | K33: =IF(E33>G33,"PASADO",(IF(AND(E33>=G33-$M$2,E33<=G33),"PRÓXIMO","VIGENTE"))) -> VIGENTE | L33: =IF(F33>H33,"PASADO",(IF(AND(F33>=H33-$N$2,F33<=H33),"PRÓXIMO","VIGENTE"))) -> PRÓXIMO
A34: ='RECURSO ACTUAL'!A35 -> 2927 | B34: ='RECURSO ACTUAL'!F35 -> 46318 | C34: ='RECURSO ACTUAL'!B35 -> 02-Medellin | D34: =VLOOKUP(A34,'Q LUB'!A:L,8,FALSE) -> 46070 | E34: =ABS(D34-TODAY()) -> 146 | F34: =VLOOKUP(A34,'Q LUB'!A:L,7,FALSE) -> 4990 | G34: =VLOOKUP(A34,'Q LUB'!A:L,5,FALSE) -> 180 | H34: =VLOOKUP(A34,'Q LUB'!A:L,4,FALSE) -> 5000 | I34: =G34-E34 -> 34 | J34: =H34-F34 -> 10 | K34: =IF(E34>G34,"PASADO",(IF(AND(E34>=G34-$M$2,E34<=G34),"PRÓXIMO","VIGENTE"))) -> VIGENTE | L34: =IF(F34>H34,"PASADO",(IF(AND(F34>=H34-$N$2,F34<=H34),"PRÓXIMO","VIGENTE"))) -> PRÓXIMO
A35: ='RECURSO ACTUAL'!A36 -> 2926 | B35: ='RECURSO ACTUAL'!F36 -> 46318 | C35: ='RECURSO ACTUAL'!B36 -> 31-Copacabana | D35: =VLOOKUP(A35,'Q LUB'!A:L,8,FALSE) -> 46101 | E35: =ABS(D35-TODAY()) -> 115 | F35: =VLOOKUP(A35,'Q LUB'!A:L,7,FALSE) -> 4791 | G35: =VLOOKUP(A35,'Q LUB'!A:L,5,FALSE) -> 180 | H35: =VLOOKUP(A35,'Q LUB'!A:L,4,FALSE) -> 5000 | I35: =G35-E35 -> 65 | J35: =H35-F35 -> 209 | K35: =IF(E35>G35,"PASADO",(IF(AND(E35>=G35-$M$2,E35<=G35),"PRÓXIMO","VIGENTE"))) -> VIGENTE | L35: =IF(F35>H35,"PASADO",(IF(AND(F35>=H35-$N$2,F35<=H35),"PRÓXIMO","VIGENTE"))) -> PRÓXIMO
A36: ='RECURSO ACTUAL'!A37 -> 2925 | B36: ='RECURSO ACTUAL'!F37 -> 46318 | C36: ='RECURSO ACTUAL'!B37 -> 02-Medellin | D36: =VLOOKUP(A36,'Q LUB'!A:L,8,FALSE) -> 46087 | E36: =ABS(D36-TODAY()) -> 129 | F36: =VLOOKUP(A36,'Q LUB'!A:L,7,FALSE) -> 5412 | G36: =VLOOKUP(A36,'Q LUB'!A:L,5,FALSE) -> 180 | H36: =VLOOKUP(A36,'Q LUB'!A:L,4,FALSE) -> 5000 | I36: =G36-E36 -> 51 | J36: =H36-F36 -> -412 | K36: =IF(E36>G36,"PASADO",(IF(AND(E36>=G36-$M$2,E36<=G36),"PRÓXIMO","VIGENTE"))) -> VIGENTE | L36: =IF(F36>H36,"PASADO",(IF(AND(F36>=H36-$N$2,F36<=H36),"PRÓXIMO","VIGENTE"))) -> PASADO
A37: ='RECURSO ACTUAL'!A38 -> 2924 | B37: ='RECURSO ACTUAL'!F38 -> 46318 | C37: ='RECURSO ACTUAL'!B38 -> 02-Medellin | D37: =VLOOKUP(A37,'Q LUB'!A:L,8,FALSE) -> 46155 | E37: =ABS(D37-TODAY()) -> 61 | F37: =VLOOKUP(A37,'Q LUB'!A:L,7,FALSE) -> 2198 | G37: =VLOOKUP(A37,'Q LUB'!A:L,5,FALSE) -> 180 | H37: =VLOOKUP(A37,'Q LUB'!A:L,4,FALSE) -> 5000 | I37: =G37-E37 -> 119 | J37: =H37-F37 -> 2802 | K37: =IF(E37>G37,"PASADO",(IF(AND(E37>=G37-$M$2,E37<=G37),"PRÓXIMO","VIGENTE"))) -> VIGENTE | L37: =IF(F37>H37,"PASADO",(IF(AND(F37>=H37-$N$2,F37<=H37),"PRÓXIMO","VIGENTE"))) -> VIGENTE
A38: ='RECURSO ACTUAL'!A39 -> 2923 | B38: ='RECURSO ACTUAL'!F39 -> 46318 | C38: ='RECURSO ACTUAL'!B39 -> BULTOS | D38: =VLOOKUP(A38,'Q LUB'!A:L,8,FALSE) -> 46135 | E38: =ABS(D38-TODAY()) -> 81 | F38: =VLOOKUP(A38,'Q LUB'!A:L,7,FALSE) -> 5969 | G38: =VLOOKUP(A38,'Q LUB'!A:L,5,FALSE) -> 180 | H38: =VLOOKUP(A38,'Q LUB'!A:L,4,FALSE) -> 5000 | I38: =G38-E38 -> 99 | J38: =H38-F38 -> -969 | K38: =IF(E38>G38,"PASADO",(IF(AND(E38>=G38-$M$2,E38<=G38),"PRÓXIMO","VIGENTE"))) -> VIGENTE | L38: =IF(F38>H38,"PASADO",(IF(AND(F38>=H38-$N$2,F38<=H38),"PRÓXIMO","VIGENTE"))) -> PASADO
A39: ='RECURSO ACTUAL'!A40 -> 2922 | B39: ='RECURSO ACTUAL'!F40 -> 46318 | C39: ='RECURSO ACTUAL'!B40 -> 02-Medellin | D39: =VLOOKUP(A39,'Q LUB'!A:L,8,FALSE) -> 46062 | E39: =ABS(D39-TODAY()) -> 154 | F39: =VLOOKUP(A39,'Q LUB'!A:L,7,FALSE) -> 4383 | G39: =VLOOKUP(A39,'Q LUB'!A:L,5,FALSE) -> 180 | H39: =VLOOKUP(A39,'Q LUB'!A:L,4,FALSE) -> 5000 | I39: =G39-E39 -> 26 | J39: =H39-F39 -> 617 | K39: =IF(E39>G39,"PASADO",(IF(AND(E39>=G39-$M$2,E39<=G39),"PRÓXIMO","VIGENTE"))) -> VIGENTE | L39: =IF(F39>H39,"PASADO",(IF(AND(F39>=H39-$N$2,F39<=H39),"PRÓXIMO","VIGENTE"))) -> PRÓXIMO
A40: ='RECURSO ACTUAL'!A41 -> 2921 | B40: ='RECURSO ACTUAL'!F41 -> 46318 | C40: ='RECURSO ACTUAL'!B41 -> MAYORCA | D40: =VLOOKUP(A40,'Q LUB'!A:L,8,FALSE) -> 46056 | E40: =ABS(D40-TODAY()) -> 160 | F40: =VLOOKUP(A40,'Q LUB'!A:L,7,FALSE) -> 4653 | G40: =VLOOKUP(A40,'Q LUB'!A:L,5,FALSE) -> 180 | H40: =VLOOKUP(A40,'Q LUB'!A:L,4,FALSE) -> 5000 | I40: =G40-E40 -> 20 | J40: =H40-F40 -> 347 | K40: =IF(E40>G40,"PASADO",(IF(AND(E40>=G40-$M$2,E40<=G40),"PRÓXIMO","VIGENTE"))) -> VIGENTE | L40: =IF(F40>H40,"PASADO",(IF(AND(F40>=H40-$N$2,F40<=H40),"PRÓXIMO","VIGENTE"))) -> PRÓXIMO
... A223: ='RECURSO ACTUAL'!A224 | B223: ='RECURSO ACTUAL'!F224 | C223: ='RECURSO ACTUAL'!B224 | D223: =VLOOKUP(A223,'Q LUB'!A:L,8,FALSE) -> #N/A | E223: =ABS(D223-TODAY()) -> #N/A | F223: =VLOOKUP(A223,'Q LUB'!A:L,7,FALSE) -> #N/A | G223: =VLOOKUP(A223,'Q LUB'!A:L,5,FALSE) -> #N/A | H223: =VLOOKUP(A223,'Q LUB'!A:L,4,FALSE) -> #N/A | I223: =G223-E223 -> #N/A | J223: =H223-F223 -> #N/A | K223: =IF(E223>G223,"PASADO",(IF(AND(E223>=G223-$M$2,E223<=G223),"PRÓXIMO","VIGENTE"))) -> #N/A | L223: =IF(F223>H223,"PASADO",(IF(AND(F223>=H223-$N$2,F223<=H223),"PRÓXIMO","VIGENTE"))) -> #N/A
A224: ='RECURSO ACTUAL'!A226
A225: ='RECURSO ACTUAL'!A227
A226: ='RECURSO ACTUAL'!A228
A227: ='RECURSO ACTUAL'!A229
A228: ='RECURSO ACTUAL'!A230
A229: ='RECURSO ACTUAL'!A231
A230: ='RECURSO ACTUAL'!A232
A231: ='RECURSO ACTUAL'!A233
A232: ='RECURSO ACTUAL'!A234
A233: ='RECURSO ACTUAL'!A235
A234: ='RECURSO ACTUAL'!A236
A235: ='RECURSO ACTUAL'!A237
...

Sheet Q MPP
A1: Móvil | B1: Linea Vehículo | C1: Terminal | D1: Frecuencia KM | E1: Frecuencia Días | F1: Diferencia Días | G1: Diferencia KMs | H1: Fecha de Terminación de la Orden | I1: Fecha Actual | J1: Estado | K1: Orden de Trabajo | L1: KMs último MPP | M1: Última Ubicación
A2: 451 | B2: Tractomula International Eagle 9400 | C2: 98. Ruta Nacional | D2: 10000 | E2: 90 | F2: 23 | G2: 8810.3 | H2: 46189 | I2: 46212 | J2: Vigente | K2: 1161824 | L2: 2226205.5 | M2: 2. Medellin
A3: 461 | B3: Tractomula International Eagle 9400 | C3: 2. Medellin | D3: 10000 | E3: 90 | F3: 86 | G3: 8013.7 | H3: 46126 | I3: 46212 | J3: Vigente | K3: 1156100 | L3: 1276855.6 | M3: 31. Copacabana
A4: 463 | B4: Tractomula International Eagle 9400 | C4: 98. Ruta Nacional | D4: 10000 | E4: 60 | F4: 56 | G4: 15920.8 | H4: 46156 | I4: 46212 | J4: Pasado | K4: 1159885 | L4: 1845598 | M4: 2. Medellin
A5: 464 | B5: Tractomula International Eagle 9400 | C5: 2. Medellin | D5: 10000 | E5: 90 | F5: 142 | G5: 8507.3 | H5: 46070 | I5: 46212 | J5: Pasado | K5: 1150098 | L5: 1492920.9 | M5: 24. Rionegro
A6: 467 | B6: Tractomula International Eagle 9400 | C6: 98. Ruta Nacional | D6: 10000 | E6: 60 | F6: 87 | G6: 32986.2 | H6: 46125 | I6: 46212 | J6: Pasado | K6: 1155919 | L6: 1625697.1 | M6: 1. Bogota
A7: 471 | B7: Tractomula International Eagle 9400 | C7: 98. Ruta Nacional | D7: 10000 | E7: 60 | F7: 21 | G7: 7086 | H7: 46191 | I7: 46212 | J7: Vigente | K7: 1161863 | L7: 1698539.3 | M7: 6. Bucaramanga
A8: 472 | B8: Tractomula International Eagle 9400 | C8: 2. Medellin | D8: 10000 | E8: 90 | F8: 55 | G8: 5692.9 | H8: 46157 | I8: 46212 | J8: Vigente | K8: 1159975 | L8: 1591924.5 | M8: 24. Rionegro
A9: 473 | B9: Tractomula International Eagle 9400 | C9: 98. Ruta Nacional | D9: 10000 | E9: 60 | F9: 147 | G9: 18755.9 | H9: 46065 | I9: 46212 | J9: Pasado | K9: 1149531 | L9: 1684009.6 | M9: 2. Medellin
A10: 475 | B10: Tractomula International Eagle 9400 | C10: 98. Ruta Nacional | D10: 10000 | E10: 60 | F10: 84 | G10: 19149.4 | H10: 46128 | I10: 46212 | J10: Pasado | K10: 1156406 | L10: 1622905.2 | M10: 4. Pereira
A11: 477 | B11: Tractomula International Eagle 9400 | C11: 98. Ruta Nacional | D11: 10000 | E11: 60 | F11: 16 | G11: 4156.7 | H11: 46196 | I11: 46212 | J11: Vigente | K11: 1161933 | L11: 1592403.1 | M11: 1. Bogota
A12: 478 | B12: Tractomula International Eagle 9400 | C12: 98. Ruta Nacional | D12: 10000 | E12: 60 | F12: 30 | G12: 10476.6 | H12: 46182 | I12: 46212 | J12: Pasado | K12: 1161695 | L12: 1460648.6 | M12: 1. Bogota
A13: 481 | B13: Tractomula International Eagle 9400 | C13: 2. Medellin | D13: 10000 | E13: 90 | F13: 56 | G13: 5912.6 | H13: 46156 | I13: 46212 | J13: Vigente | K13: 1159896 | L13: 1139335.7 | M13: 2. Medellin
... A435: 3284 | B435: Furgon Foton 1030 | C435: 2. Medellin | D435: 5000 | E435: 90 | F435: 65 | G435: 2493 | H435: 46147 | I435: 46212 | J435: Vigente | K435: 1158481 | L435: 7253 | M435: Sin Última Ubicación
A436: 222129 | B436: Tractomula Dongfeng Dfh4250c7 | C436: 98. Ruta Nacional | D436: 0 | E436: 0 | F436: 0 | G436: 0 | H436: - | I436: 46212 | J436: Pendiente | K436: - | L436: 0 | M436: 31. Copacabana
A437: 222134 | B437: Van Citroen Berlingo | C437: 2. Medellin | D437: 0 | E437: 0 | F437: 0 | G437: 0 | H437: - | I437: 46212 | J437: Pendiente | K437: - | L437: 0 | M437: Sin Última Ubicación

Sheet LUBRICACION
B2: LUBRICACIÒN MOTOR POR TIEMPO | K2: LUBRICACIÒN MOTOR POR KM | T2: GESTIÓN LUB | AJ2: LUBRICACIÒN CAJA Y TRA POR TIEMPO | AP2: LUBRICACIÒN CAJA Y TRA POR KM | AV2: LUBRICACIÒN CAJA Y TRA POR TIEMPO
B3: ORDEN | C3: MÓVIL | D3: DESCRIPCIÓN | E3: POBLACIÓN | F3: FECHA ULT LUB | G3: ORDEN PRIORIDAD | H3: ESTADO | I3: ESTADO GESTIÓN | K3: ORDEN | L3: MÓVIL | M3: DESCRIPCIÓN | N3: POBLACIÓN | O3: FECHA ULT LUB | P3: ORDEN PRIORIDAD | Q3: ESTADO | R3: ESTADO GESTIÓN | T3: HECHOS | U3: PEDIDOS | W3: PROPORCIÓN | AJ3: ORDEN | AK3: =IFERROR(__xludf.DUMMYFUNCTION("QUERY('BD LUB'!A1:S58,""SELECT B,C,E,N ORDER BY E DESC"",1)"),"DESCRIPCIÓN") -> DESCRIPCIÓN | AL3: =IFERROR(__xludf.DUMMYFUNCTION("""COMPUTED_VALUE"""),"POBLACIÓN") -> POBLACIÓN | AM3: =IFERROR(__xludf.DUMMYFUNCTION("""COMPUTED_VALUE"""),"TIEMPO DEL ACEITE") -> TIEMPO DEL ACEITE | AN3: =IFERROR(__xludf.DUMMYFUNCTION("""COMPUTED_VALUE"""),"KM DE PRÓXIMO") -> KM DE PRÓXIMO | AP3: ORDEN | AQ3: =IFERROR(__xludf.DUMMYFUNCTION("QUERY('BD LUB'!A1:S58,""SELECT B,C,E,N ORDER BY E DESC"",1)"),"DESCRIPCIÓN") -> DESCRIPCIÓN | AR3: =IFERROR(__xludf.DUMMYFUNCTION("""COMPUTED_VALUE"""),"POBLACIÓN") -> POBLACIÓN | AS3: =IFERROR(__xludf.DUMMYFUNCTION("""COMPUTED_VALUE"""),"TIEMPO DEL ACEITE") -> TIEMPO DEL ACEITE | AT3: =IFERROR(__xludf.DUMMYFUNCTION("""COMPUTED_VALUE"""),"KM DE PRÓXIMO") -> KM DE PRÓXIMO | AV3: ORDEN | AW3: =IFERROR(__xludf.DUMMYFUNCTION("QUERY('BD LUB'!R1:AE58,""SELECT B,C,E,N ORDER BY E DESC"",1)"),"#VALUE!") -> #VALUE!
B4: 1 | C4: =IFERROR(__xludf.DUMMYFUNCTION("QUERY('BD LUB'!$A$2:$L$223,""SELECT A,B,C,D,I,K ORDER BY I ASC"")"),982.0) -> 982 | D4: =IFERROR(__xludf.DUMMYFUNCTION("""COMPUTED_VALUE"""),46551.0) -> 46551 | E4: =IFERROR(__xludf.DUMMYFUNCTION("""COMPUTED_VALUE"""),"02-Medellin") -> 02-Medellin | H4: =IFERROR(__xludf.DUMMYFUNCTION("""COMPUTED_VALUE"""),"#N/A") -> #N/A | I4: =IF(OR(H4="PASADO",H4="PRÓXIMO"), IF(AND(NOT(ISERROR(MATCH(C4,$T$4:$T$195,0))),NOT(ISERROR(MATCH(C4,$U$4:$U$195,0)))),"HECHO",IF(NOT(ISERROR(MATCH(C4,$U$4:$U$195,0))),"PEDIDO","NO PEDIDO")),"-") -> - | K4: 1 | L4: =IFERROR(__xludf.DUMMYFUNCTION("QUERY('BD LUB'!$A$2:$L$223,""SELECT A,B,C,D,J,L ORDER BY J ASC"")"),982.0) -> 982 | M4: =IFERROR(__xludf.DUMMYFUNCTION("""COMPUTED_VALUE"""),46551.0) -> 46551 | N4: =IFERROR(__xludf.DUMMYFUNCTION("""COMPUTED_VALUE"""),"02-Medellin") -> 02-Medellin | Q4: =IFERROR(__xludf.DUMMYFUNCTION("""COMPUTED_VALUE"""),"#N/A") -> #N/A | T4: =CALENDARIO!D16 -> 2425 | U4: =CALENDARIO!C16 -> 2880 | W4: =IFERROR(__xludf.DUMMYFUNCTION("FLATTEN(QUERY(LUBRICACION!C8:I225,""SELECT C WHERE I='NO PEDIDO' ""),QUERY(LUBRICACION!L8:R225,""SELECT L WHERE R='NO PEDIDO'""))"),495.0) -> 495 | X4: =(VLOOKUP(W4,'BD LUB'!$A$2:$L$223,5,FALSE)/VLOOKUP(W4,'BD LUB'!$A$2:$L$223,7,FALSE))+(VLOOKUP(W4,'BD LUB'!$A$2:$L$223,6,FALSE)/VLOOKUP(W4,'BD LUB'!$A$2:$L$223,8,FALSE)) -> 1.5310456 | Y4: =IF(AND(VLOOKUP(W4,'BD LUB'!$A$2:$L$223,11,FALSE)="PASADO",VLOOKUP(W4,'BD LUB'!$A$2:$L$223,12,FALSE)="PASADO"),1,IF(OR(AND(VLOOKUP(W4,'BD LUB'!$A$2:$L$223,11,FALSE)="PASADO",VLOOKUP(W4,'BD LUB'!$A$2:$L$223,12,FALSE)="PRÓXIMO"),AND(VLOOKUP(W4,'BD LUB'!$A$2:$L$223,11,FALSE)="PRÓXIMO",VLOOKUP(W4,'BD LUB'!$A$2:$L$223,12,FALSE)="PASADO")),2,IF(OR(AND(VLOOKUP(W4,'BD LUB'!$A$2:$L$223,11,FALSE)="PASADO",VLOOKUP(W4,'BD LUB'!$A$2:$L$223,12,FALSE)="VIGENTE"),AND(VLOOKUP(W4,'BD LUB'!$A$2:$L$223,11,FALSE)="VIGENTE",VLOOKUP(W4,'BD LUB'!$A$2:$L$223,12,FALSE)="PASADO")),3,IF(AND(VLOOKUP(W4,'BD LUB'!$A$2:$L$223,11,FALSE)="PRÓXIMO",VLOOKUP(W4,'BD LUB'!$A$2:$L$223,12,FALSE)="PRÓXIMO"),4,IF(OR(AND(VLOOKUP(W4,'BD LUB'!$A$2:$L$223,11,FALSE)="PRÓXIMO",VLOOKUP(W4,'BD LUB'!$A$2:$L$223,12,FALSE)="VIGENTE"),AND(VLOOKUP(W4,'BD LUB'!$A$2:$L$223,11,FALSE)="VIGENTE",VLOOKUP(W4,'BD LUB'!$A$2:$L$223,12,FALSE)="PRÓXIMO")),5,IF(AND(VLOOKUP(W4,'BD LUB'!$A$2:$L$223,11,FALSE)="VIGENTE",VLOOKUP(W4,'BD LUB'!$A$2:$L$223,12,FALSE)="VIGENTE"),6,"No definido")))))) -> 3 | Z4: =IFERROR(__xludf.DUMMYFUNCTION("FLATTEN(QUERY(LUBRICACION!C8:I226,""SELECT C WHERE (H='PASADO' OR H='PRÓXIMO') AND (I='PEDIDO' OR I='NO PEDIDO')""),QUERY(LUBRICACION!L8:R226,""SELECT L WHERE (Q='PASADO' OR Q='PRÓXIMO') AND (R='PEDIDO' OR R='NO PEDIDO')""))"),2392.0) -> 2392 | AA4: =(VLOOKUP(Z4,'BD LUB'!$A$2:$L$223,5,FALSE)/VLOOKUP(Z4,'BD LUB'!$A$2:$L$223,7,FALSE))+(VLOOKUP(Z4,'BD LUB'!$A$2:$L$223,6,FALSE)/VLOOKUP(Z4,'BD LUB'!$A$2:$L$223,8,FALSE)) -> 2.1406811 | AB4: =IF(AND(VLOOKUP(Z4,'BD LUB'!$A$2:$L$223,11,FALSE)="PASADO",VLOOKUP(Z4,'BD LUB'!$A$2:$L$223,12,FALSE)="PASADO"),1,IF(OR(AND(VLOOKUP(Z4,'BD LUB'!$A$2:$L$223,11,FALSE)="PASADO",VLOOKUP(Z4,'BD LUB'!$A$2:$L$223,12,FALSE)="PRÓXIMO"),AND(VLOOKUP(Z4,'BD LUB'!$A$2:$L$223,11,FALSE)="PRÓXIMO",VLOOKUP(Z4,'BD LUB'!$A$2:$L$223,12,FALSE)="PASADO")),2,IF(OR(AND(VLOOKUP(Z4,'BD LUB'!$A$2:$L$223,11,FALSE)="PASADO",VLOOKUP(Z4,'BD LUB'!$A$2:$L$223,12,FALSE)="VIGENTE"),AND(VLOOKUP(Z4,'BD LUB'!$A$2:$L$223,11,FALSE)="VIGENTE",VLOOKUP(Z4,'BD LUB'!$A$2:$L$223,12,FALSE)="PASADO")),3,IF(AND(VLOOKUP(Z4,'BD LUB'!$A$2:$L$223,11,FALSE)="PRÓXIMO",VLOOKUP(Z4,'BD LUB'!$A$2:$L$223,12,FALSE)="PRÓXIMO"),4,IF(OR(AND(VLOOKUP(Z4,'BD LUB'!$A$2:$L$223,11,FALSE)="PRÓXIMO",VLOOKUP(Z4,'BD LUB'!$A$2:$L$223,12,FALSE)="VIGENTE"),AND(VLOOKUP(Z4,'BD LUB'!$A$2:$L$223,11,FALSE)="VIGENTE",VLOOKUP(Z4,'BD LUB'!$A$2:$L$223,12,FALSE)="PRÓXIMO")),5,IF(AND(VLOOKUP(Z4,'BD LUB'!$A$2:$L$223,11,FALSE)="VIGENTE",VLOOKUP(Z4,'BD LUB'!$A$2:$L$223,12,FALSE)="VIGENTE"),6,"No definido")))))) -> 3 | AC4: =IFERROR(__xludf.DUMMYFUNCTION("UNIQUE(QUERY(LUBRICACION!Z4:AB226,""SELECT Z ORDER BY AA DESC, AB ASC""))"),2671.0) -> 2671 | AD4: =IF(VLOOKUP(AC4,'BD LUB'!$A$2:$C$223,3,FALSE)=$AH$20,AC4&" MED",IF(VLOOKUP(AC4,'BD LUB'!$A$2:$C$223,3,FALSE)=$AH$19,AC4&" MAY",IF(VLOOKUP(AC4,'BD LUB'!$A$2:$C$223,3,FALSE)=$AH$18,AC4&" RN",IF(VLOOKUP(AC4,'BD LUB'!$A$2:$C$223,3,FALSE)=$AH$17,AC4&" COPQUI",IF(VLOOKUP(AC4,'BD LUB'!$A$2:$C$223,3,FALSE)=$AH$16,AC4&" CEJ",IF(VLOOKUP(AC4,'BD LUB'!$A$2:$C$223,3,FALSE)=$AH$15,AC4&" BULT",IF(VLOOKUP(AC4,'BD LUB'!$A$2:$C$223,3,FALSE)=$AH$14,AC4&" COP",IF(VLOOKUP(AC4,'BD LUB'!$A$2:$C$223,3,FALSE)=$AH$13,AC4&" RIO",IF(VLOOKUP(AC4,'BD LUB'!$A$2:$C$223,3,FALSE)=$AH$21,AC4&" APART","Dato no encontrado"))))))))) -> 2671 MAY | AJ4: 1 | AK4: =IFERROR(__xludf.DUMMYFUNCTION("""COMPUTED_VALUE"""),46661.0) -> 46661 | AL4: =IFERROR(__xludf.DUMMYFUNCTION("""COMPUTED_VALUE"""),"02-Medellin") -> 02-Medellin | AM4: =IFERROR(__xludf.DUMMYFUNCTION("""COMPUTED_VALUE"""),174.0) -> 174 | AP4: 1 | AQ4: =IFERROR(__xludf.DUMMYFUNCTION("""COMPUTED_VALUE"""),46661.0) -> 46661 | AR4: =IFERROR(__xludf.DUMMYFUNCTION("""COMPUTED_VALUE"""),"02-Medellin") -> 02-Medellin | AS4: =IFERROR(__xludf.DUMMYFUNCTION("""COMPUTED_VALUE"""),174.0) -> 174 | AV4: 1
